Traceback (most recent call last):
  File "/home/jubayer/anaconda3/envs/ds-books/lib/python3.8/site-packages/jupyter_cache/executors/utils.py", line 51, in single_nb_execution
    executenb(
  File "/home/jubayer/.local/lib/python3.8/site-packages/nbclient/client.py", line 1112, in execute
    return NotebookClient(nb=nb, resources=resources, km=km, **kwargs).execute()
  File "/home/jubayer/.local/lib/python3.8/site-packages/nbclient/util.py", line 74, in wrapped
    return just_run(coro(*args, **kwargs))
  File "/home/jubayer/.local/lib/python3.8/site-packages/nbclient/util.py", line 53, in just_run
    return loop.run_until_complete(coro)
  File "/home/jubayer/anaconda3/envs/ds-books/lib/python3.8/asyncio/base_events.py", line 616, in run_until_complete
    return future.result()
  File "/home/jubayer/.local/lib/python3.8/site-packages/nbclient/client.py", line 553, in async_execute
    await self.async_execute_cell(
  File "/home/jubayer/.local/lib/python3.8/site-packages/nbclient/client.py", line 857, in async_execute_cell
    self._check_raise_for_error(cell, exec_reply)
  File "/home/jubayer/.local/lib/python3.8/site-packages/nbclient/client.py", line 760, in _check_raise_for_error
    raise CellExecutionError.from_cell_and_msg(cell, exec_reply_content)
nbclient.exceptions.CellExecutionError: An error occurred while executing the following cell:
------------------
# create a publication quality table 
table = create_table(gapminder.head(10))
py.iplot(table)
------------------

[0;31m---------------------------------------------------------------------------[0m
[0;31mNameError[0m                                 Traceback (most recent call last)
[0;32m/tmp/ipykernel_25919/1521453323.py[0m in [0;36m<module>[0;34m[0m
[1;32m      1[0m [0;31m# create a publication quality table[0m[0;34m[0m[0;34m[0m[0;34m[0m[0m
[1;32m      2[0m [0mtable[0m [0;34m=[0m [0mcreate_table[0m[0;34m([0m[0mgapminder[0m[0;34m.[0m[0mhead[0m[0;34m([0m[0;36m10[0m[0;34m)[0m[0;34m)[0m[0;34m[0m[0;34m[0m[0m
[0;32m----> 3[0;31m [0mpy[0m[0;34m.[0m[0miplot[0m[0;34m([0m[0mtable[0m[0;34m)[0m[0;34m[0m[0;34m[0m[0m
[0m
[0;31mNameError[0m: name 'py' is not defined
NameError: name 'py' is not defined

